<?xml version="1.0"?>
<robot xmlns:xacro="http://wiki.ros.org/xacro">

  <xacro:macro name="flat_bot" params="prefix">
  
    <!-- ROS Control Plugin used to drive joints -->
    <gazebo>
      <plugin name="gazebo_ros_control" filename="libgazebo_ros_control.so">
        <!--robotNamespace></robotNamespace-->
      </plugin>
    </gazebo>
  
    <!-- placeholder links to define the connector coordinate frames of each end effector -->
    <link name="${prefix}sirom_a_origin">
    </link>   
    <link name="${prefix}sirom_b_origin">
    </link>   
  
    <!-- links: main serial chain -->
    <link name="${prefix}sirom_a_link">
      <visual>
        <origin xyz="0 0 0" rpy="0 0 0"/>
        <geometry>
          <mesh filename="package://flat_bot_support/meshes/visual/sirom_link_a.stl" />
        </geometry>
      </visual>
      <collision>
        <origin xyz="0 0 0" rpy="0 0 0"/>
        <geometry>
          <mesh filename="package://flat_bot_support/meshes/collision/sirom_link_a_collision.stl" />
        </geometry>
      </collision>
      <inertial>
        <mass value="0.443"/>
        <origin xyz="0.058467 -0.00054 0.038125" rpy="-0.029845130209103 0.0607374579694027 -0.629540261194355" />
        <inertia
          ixx="0.000608839" ixy="0.0" ixz="0.0"
          iyy="0.000540307" iyz="0.0"
          izz="0.001015708" />
      </inertial>
    </link>
    
    <link name="${prefix}link_a">
      <visual>
        <origin xyz="0 0 0" rpy="0 0 0"/>
        <geometry>
          <mesh filename="package://flat_bot_support/meshes/visual/arm_link_a.stl" />
        </geometry>
      </visual>
      <collision>
        <origin xyz="0 0 0" rpy="0.0 0.0 0.0" />
        <geometry>
          <mesh filename="package://flat_bot_support/meshes/collision/arm_link_a_collision.stl" />
        </geometry>
      </collision>
      <inertial>
        <mass value="0.537"/>\n
        <origin xyz="0.125 0 0.029919" rpy="0 0 0" />
        <inertia
          ixx="0.000202697" ixy="0.0" ixz="0.0"
          iyy="0.003563004" iyz="0.0"
          izz="0.003438567" />
      </inertial>
    </link>
    
    <link name="${prefix}link_b">
      <visual>
        <origin xyz="0 0 0" rpy="0 0 0"/>
        <geometry>
          <mesh filename="package://flat_bot_support/meshes/visual/arm_link_b.stl" />
        </geometry>
      </visual>
      <collision>
        <origin xyz="0 0 0" rpy="0 0 0"/>
        <geometry>
          <mesh filename="package://flat_bot_support/meshes/collision/arm_link_b_collision.stl" />
        </geometry>
      </collision>
      <inertial>
        <mass value="0.659"/>
        <origin xyz="0.100912 -0.000004 0.03578" rpy="0.000174532925199433 -0.0146607657167524 0" />
        <inertia
          ixx="0.000256681" ixy="0.0" ixz="0.0"
          iyy="0.004570271" iyz="0.0"
          izz="0.004633015" />
      </inertial>
    </link>
    
    <link name="${prefix}sirom_b_link">
      <visual>
        <origin xyz="0 0 0" rpy="0 0 0"/>
        <geometry>
          <mesh filename="package://flat_bot_support/meshes/visual/sirom_link_b.stl" />
        </geometry>
      </visual>
      <collision>
        <origin xyz="0 0 0" rpy="0 0 0"/>
        <geometry>
          <mesh filename="package://flat_bot_support/meshes/collision/sirom_link_b_collision.stl" />
        </geometry>
      </collision>
      <inertial>
        <mass value="0.443"/>
        <origin xyz="0.04189 0.00054 0.038125" rpy="0.029845130209103 -0.0607374579694027 -0.629540261194355" />
        <inertia
          ixx="0.000608839" ixy="0.0" ixz="0.0"
          iyy="0.000540307" iyz="0.0"
          izz="0.001015708" />
      </inertial>
    </link>
    
    <!--link name="${prefix}sirom_b_latch">
      <visual>
        <origin xyz="0 0 0" rpy="0 0 0"/>
        <geometry>
          <mesh filename="package://flat_bot_support/meshes/visual/sirom_latch_visual.stl" />
        </geometry>
      </visual>
      <collision>
        <origin xyz="0 0 0" rpy="0 0 0"/>
        <geometry>
          <mesh filename="package://flat_bot_support/meshes/collision/sirom_latch_collision.stl" />
        </geometry>
      </collision>
      <inertial>
        <mass value="0.038" />
        <origin xyz="-0.021394 -0.001309 0" rpy="0 0 -0.044331363000656" />
        <inertia
            ixx="0.000020967" ixy="0.0" ixz="0.0"
            iyy="0.000007495" iyz="0.0"
            izz="0.000027196" />
      </inertial>
    </link-->

    <!-- transforms from the standard SIROM frame to the sirom_a link -->
    <joint name="${prefix}sirom_a_origin-link" type="fixed">
      <origin xyz="0 0 0" rpy="0 0 ${pi}"/>
      <parent link="${prefix}sirom_a_origin"/>
      <child link="${prefix}sirom_a_link"/>
    </joint>

    <!-- joints: main serial chain -->
    <joint name="${prefix}wrist_a_joint" type="revolute">
      <origin xyz="0.100357 0 0" rpy="0 0 0"/>
      <parent link="${prefix}sirom_a_link"/>
      <child link="${prefix}link_a"/>
      <axis xyz="0 0 1"/>
      <limit lower="${-pi/2.0}" upper="${pi/2.0}" effort="100" velocity="3.67"/>
    </joint>
    <joint name="${prefix}elbow_joint" type="revolute">
      <origin xyz="0.25 0 0" rpy="0 0 0"/>
      <parent link="${prefix}link_a"/>
      <child link="${prefix}link_b"/>
      <axis xyz="0 0 1"/>
      <limit lower="-2.96706" upper="2.96706" effort="100" velocity="3.32"/>
    </joint>
    <joint name="${prefix}wrist_b_joint" type="revolute">
      <origin xyz="0.25 0 0" rpy="0 0 0"/>
      <parent link="${prefix}link_b"/>
      <child link="${prefix}sirom_b_link"/>
      <axis xyz="0 0 1"/>
      <limit lower="${-pi/2.0}" upper="${pi/2.0}" effort="100" velocity="3.67"/>
    </joint>
    
    <!--joint name="${prefix}latch_b_joint" type="revolute">
      <origin xyz="0.0565 -0.021472 0.038" rpy="0 0 ${-pi/4}"/>
      <parent link="${prefix}sirom_b_link"/>
      <child link="${prefix}sirom_b_latch"/>
      <axis xyz="0 0 1"/>
      <limit lower="${-pi/2.0}" upper="${pi/2.0}" effort="100" velocity="3.67"/>
    </joint-->

    <!-- transform from the standard SIROM frame to the sirom_b link -->
    <joint name="${prefix}sirom_b_link-origin" type="fixed">
      <origin xyz="0.0785 -0.0213 0" rpy="0 0 0" />
      <parent link="${prefix}sirom_b_link" />
      <child link="${prefix}sirom_b_origin" />
    </joint>
    
    <!-- ================= Arm Joint Transmissions ==================== -->
    <transmission name="wrist_a_trans">
      <type>transmission_interface/SimpleTransmission</type>
      <joint name="${prefix}wrist_a_joint">
        <hardwareInterface>hardware_interface/EffortJointInterface</hardwareInterface>
      </joint>
      <actuator name="wrist_a_motor">
        <mechanicalReduction>50</mechanicalReduction>
      </actuator>
    </transmission>
    
    <transmission name="elbow_trans">
      <type>transmission_interface/SimpleTransmission</type>
      <joint name="${prefix}elbow_joint">
        <hardwareInterface>hardware_interface/EffortJointInterface</hardwareInterface>
      </joint>
      <actuator name="elbow_motor">
        <mechanicalReduction>50</mechanicalReduction>
      </actuator>
    </transmission>
    
    <transmission name="wrist_b_trans">
      <type>transmission_interface/SimpleTransmission</type>
      <joint name="${prefix}wrist_b_joint">
        <hardwareInterface>hardware_interface/EffortJointInterface</hardwareInterface>
      </joint>
      <actuator name="wrist_b_motor">
        <mechanicalReduction>50</mechanicalReduction>
      </actuator>
    </transmission>
    
    <!-- ================= SIROM Joint Transmissions ==================== -->
    <!--transmission name="sirom_latch_b_trans">
      <type>transmission_interface/SimpleTransmission</type>
      <joint name="${prefix}latch_b_joint">
        <hardwareInterface>hardware_interface/EffortJointInterface</hardwareInterface>
      </joint>
      <actuator name="latch_b_motor">
        <mechanicalReduction>50</mechanicalReduction>
      </actuator>
    </transmission-->

  </xacro:macro>
</robot>
