<?xml version="1.0"?>
<robot xmlns:xacro="http://wiki.ros.org/xacro">

  <xacro:macro name="flat_bot" params="prefix">
    <!-- links: main serial chain -->
    <link name="${prefix}sirom_a_link">
      <visual>
        <origin xyz="0 0 0" rpy="${-pi/2.0} 0 0"/>
        <geometry>
          <mesh filename="package://flat_bot_support/meshes/visual/Sirom_Link.dae" scale="0.001 0.001 0.001"/>
        </geometry>
        <!--xacro:material_fanuc_gray40 /-->
      </visual>
      <collision>
        <origin xyz="0 0 0" rpy="${-pi/2.0} 0 0"/>
        <geometry>
          <mesh filename="package://flat_bot_support/meshes/visual/Sirom_Link.dae" scale="0.001 0.001 0.001"/>
        </geometry>
      </collision>
    </link>
    <link name="${prefix}link_a">
      <visual>
        <origin xyz="-0.0785 0.0213 0" rpy="${-pi/2.0} 0 0"/>
        <geometry>
          <mesh filename="package://flat_bot_support/meshes/visual/Link_A.dae" scale="0.001 0.001 0.001"/>
        </geometry>
        <!--xacro:material_fanuc_gray40 /-->
      </visual>
      <collision>
        <origin xyz="-0.0785 0.0213 0" rpy="${-pi/2.0} 0 0"/>
        <geometry>
          <mesh filename="package://flat_bot_support/meshes/visual/Link_A.dae" scale="0.001 0.001 0.001"/>
        </geometry>
      </collision>
    </link>
    <link name="${prefix}link_b">
      <visual>
        <origin xyz="${-0.0785 - 0.25} 0.0213 0" rpy="${-pi/2.0} 0 0"/>
        <geometry>
          <mesh filename="package://flat_bot_support/meshes/visual/Link_B.dae" scale="0.001 0.001 0.001"/>
        </geometry>
        <!--xacro:material_fanuc_gray40 /-->
      </visual>
      <collision>
        <origin xyz="${-0.0785 - 0.25} 0.0213 0" rpy="${-pi/2.0} 0 0"/>
        <geometry>
          <mesh filename="package://flat_bot_support/meshes/visual/Link_B.dae" scale="0.001 0.001 0.001"/>
        </geometry>
      </collision>
    </link>
    <link name="${prefix}sirom_b_link">
      <visual>
        <origin xyz="0.0785 -0.0213 0" rpy="${-pi/2.0} 0 ${pi}"/>
        <geometry>
          <mesh filename="package://flat_bot_support/meshes/visual/Sirom_Link_2.dae" scale="0.001 0.001 0.001"/>
        </geometry>
        <!--xacro:material_fanuc_gray40 /-->
      </visual>
      <collision>
        <origin xyz="0.0785 -0.021 0" rpy="${-pi/2.0} 0 ${pi}"/>
        <geometry>
          <mesh filename="package://flat_bot_support/meshes/visual/Sirom_Link_2.dae" scale="0.001 0.001 0.001"/>
        </geometry>
      </collision>
    </link>

    <!-- joints: main serial chain -->
    <joint name="${prefix}wrist_a_joint" type="revolute">
      <origin xyz="0.0785 -0.0213 0" rpy="0 0 0"/>
      <parent link="${prefix}sirom_a_link"/>
      <child link="${prefix}link_a"/>
      <axis xyz="0 0 1"/>
      <limit lower="${-pi/2.0}" upper="${pi/2.0}" effort="0" velocity="3.67"/>
    </joint>
    <joint name="${prefix}elbow_joint" type="revolute">
      <origin xyz="0.25 0 0" rpy="0 0 0"/>
      <parent link="${prefix}link_a"/>
      <child link="${prefix}link_b"/>
      <axis xyz="0 0 1"/>
      <limit lower="-2.96706" upper="2.96706" effort="0" velocity="3.32"/>
    </joint>
    <joint name="${prefix}wrist_b_joint" type="revolute">
      <origin xyz="0.25 0 0" rpy="0 0 0"/>
      <parent link="${prefix}link_b"/>
      <child link="${prefix}sirom_b_link"/>
      <axis xyz="0 0 1"/>
      <limit lower="${-pi/2.0}" upper="${pi/2.0}" effort="0" velocity="3.67"/>
    </joint>

    <!-- transforms from the standard SIROM frame to the sirom_a link -->
    <link name="${prefix}sirom_a_origin" />
    <joint name="${prefix}sirom_a_origin-link" type="fixed">
      <origin xyz="0 0 0" rpy="0 0 ${pi}"/>
      <parent link="${prefix}sirom_a_origin"/>
      <child link="${prefix}sirom_a_link"/>
    </joint>

    <!-- transform from the standard SIROM frame to the sirom_b link -->
    <link name="${prefix}sirom_b_origin" />
    <joint name="${prefix}sirom_b_link-origin" type="fixed">
      <origin xyz="0.0785 -0.0213 0" rpy="0 0 0" />
      <parent link="${prefix}sirom_b_link" />
      <child link="${prefix}sirom_b_origin" />
    </joint>

  </xacro:macro>
</robot>
